Traceback (most recent call last):
  File "/home/pi/.local/lib/python3.5/site-packages/urllib3/connection.py", line 157, in _new_conn
    (self._dns_host, self.port), self.timeout, **extra_kw
  File "/home/pi/.local/lib/python3.5/site-packages/urllib3/util/connection.py", line 84, in create_connection
    raise err
  File "/home/pi/.local/lib/python3.5/site-packages/urllib3/util/connection.py", line 74, in create_connection
    sock.connect(sa)
ConnectionRefusedError: [Errno 111] Connection refused

During handling of the above exception, another exception occurred:

Traceback (most recent call last):
  File "/home/pi/.local/lib/python3.5/site-packages/urllib3/connectionpool.py", line 672, in urlopen
    chunked=chunked,
  File "/home/pi/.local/lib/python3.5/site-packages/urllib3/connectionpool.py", line 387, in _make_request
    conn.request(method, url, **httplib_request_kw)
  File "/usr/lib/python3.5/http/client.py", line 1107, in request
    self._send_request(method, url, body, headers)
  File "/usr/lib/python3.5/http/client.py", line 1152, in _send_request
    self.endheaders(body)
  File "/usr/lib/python3.5/http/client.py", line 1103, in endheaders
    self._send_output(message_body)
  File "/usr/lib/python3.5/http/client.py", line 934, in _send_output
    self.send(msg)
  File "/usr/lib/python3.5/http/client.py", line 877, in send
    self.connect()
  File "/home/pi/.local/lib/python3.5/site-packages/urllib3/connection.py", line 184, in connect
    conn = self._new_conn()
  File "/home/pi/.local/lib/python3.5/site-packages/urllib3/connection.py", line 169, in _new_conn
    self, "Failed to establish a new connection: %s" % e
urllib3.exceptions.NewConnectionError: <urllib3.connection.HTTPConnection object at 0xb1063b70>: Failed to establish a new connection: [Errno 111] Connection refused

During handling of the above exception, another exception occurred:

Traceback (most recent call last):
  File "/home/pi/.local/lib/python3.5/site-packages/requests/adapters.py", line 449, in send
    timeout=timeout
  File "/home/pi/.local/lib/python3.5/site-packages/urllib3/connectionpool.py", line 720, in urlopen
    method, url, error=e, _pool=self, _stacktrace=sys.exc_info()[2]
  File "/home/pi/.local/lib/python3.5/site-packages/urllib3/util/retry.py", line 436, in increment
    raise MaxRetryError(_pool, url, error or ResponseError(cause))
urllib3.exceptions.MaxRetryError: HTTPConnectionPool(host='192.168.1.249', port=5000): Max retries exceeded with url: /agent/3 (Caused by NewConnectionError('<urllib3.connection.HTTPConnection object at 0xb1063b70>: Failed to establish a new connection: [Errno 111] Connection refused',))

During handling of the above exception, another exception occurred:

Traceback (most recent call last):
  File "main.py", line 20, in <module>
    agent, message = get_agent()
  File "/home/pi/agent/control/server.py", line 36, in get_agent
    db_agent = make_get_request('agent/' + str(id))
  File "/home/pi/agent/control/server.py", line 13, in make_get_request
    request = requests.get(full_url)
  File "/home/pi/.local/lib/python3.5/site-packages/requests/api.py", line 75, in get
    return request('get', url, params=params, **kwargs)
  File "/home/pi/.local/lib/python3.5/site-packages/requests/api.py", line 60, in request
    return session.request(method=method, url=url, **kwargs)
  File "/home/pi/.local/lib/python3.5/site-packages/requests/sessions.py", line 533, in request
    resp = self.send(prep, **send_kwargs)
  File "/home/pi/.local/lib/python3.5/site-packages/requests/sessions.py", line 646, in send
    r = adapter.send(request, **kwargs)
  File "/home/pi/.local/lib/python3.5/site-packages/requests/adapters.py", line 516, in send
    raise ConnectionError(e, request=request)
requests.exceptions.ConnectionError: HTTPConnectionPool(host='192.168.1.249', port=5000): Max retries exceeded with url: /agent/3 (Caused by NewConnectionError('<urllib3.connection.HTTPConnection object at 0xb1063b70>: Failed to establish a new connection: [Errno 111] Connection refused',))
